Workbook

Sheet Property options
A1: Area | B1: Community | C1: Status | D1: Price (R) | E1: Type | F1: Floor level | G1: Beds | H1: Parking | I1: Floor size m2 | J1: Levies (R/pm) | K1: Rates & taxes (R/pm) | L1: Pets allowed | M1: Furnished | N1: Notes / details | O1: Agent name | P1: Agent company | Q1: Agent phone | R1: WhatsApp link | S1: Agent profile URL | T1: Listing URL | U1: Listing date | V1: Scraped on | W1: Precinct (SAPS) | X1: Precinct confidence | Y1: Violent per 100k | Z1: Property per 100k | AA1: Murder per 100k | AB1: Total per 100k | AC1: Total crimes 25/26 | AD1: Murders 25/26 | AE1: Violent 25/26 | AF1: Property 25/26 | AG1: Change in total vs 24/25 | AH1: Rank (violent, 1 = best)
A2: Port Edward | B2: Port Edward | C2: Available | D2: 610000 | E2: Apartment / Flat | F2: First Floor | G2: 2 | H2: 1 parking | I2: 84 | J2: 1800 | K2: 950 | L2: No | M2: NOT STATED | N2: PRICE REDUCED *** Well located and priced to sell, this two-bedroom, two-bathroom, main en suite, first floor apartment is move in ready, and only a f | No Pets Allowed, Garden | O2: Angelique Marran | P2: RE/MAX Coast and Country Southbroom | Q2: NOT CAPTURED (reCAPTCHA) | R2: NOT AVAILABLE (needs phone) | S2: Agent profile | T2: Open listing | U2: 03 December 2024 | V2: 2026-10-08 | W2: =IFERROR(INDEX('Area safety'!$C$23:$C$41,MATCH($B2,'Area safety'!$A$23:$A$41,0)),"n/a") -> Port Edward | X2: =IFERROR(INDEX('Area safety'!$D$23:$D$41,MATCH($B2,'Area safety'!$A$23:$A$41,0)),"n/a") -> CONFIRMED | Y2: =IFERROR(INDEX('Area safety'!$F$23:$F$41,MATCH($B2,'Area safety'!$A$23:$A$41,0)),"n/a") -> 571.8582 | Z2: =IFERROR(INDEX('Area safety'!$G$23:$G$41,MATCH($B2,'Area safety'!$A$23:$A$41,0)),"n/a") -> 596.91971 | AA2: =IFERROR(INDEX('Area safety'!$H$23:$H$41,MATCH($B2,'Area safety'!$A$23:$A$41,0)),"n/a") -> 27.339834 | AB2: =IFERROR(INDEX('Area safety'!$I$23:$I$41,MATCH($B2,'Area safety'!$A$23:$A$41,0)),"n/a") -> 2039.096 | AC2: =IFERROR(INDEX('Area safety'!$F$5:$F$18,MATCH($W2,'Area safety'!$A$5:$A$18,0)),"n/a") -> 895 | AD2: =IFERROR(INDEX('Area safety'!$G$5:$G$18,MATCH($W2,'Area safety'!$A$5:$A$18,0)),"n/a") -> 12 | AE2: =IFERROR(INDEX('Area safety'!$H$5:$H$18,MATCH($W2,'Area safety'!$A$5:$A$18,0)),"n/a") -> 251 | AF2: =IFERROR(INDEX('Area safety'!$I$5:$I$18,MATCH($W2,'Area safety'!$A$5:$A$18,0)),"n/a") -> 262 | AG2: =IFERROR(INDEX('Area safety'!$K$23:$K$41,MATCH($B2,'Area safety'!$A$23:$A$41,0)),"n/a") -> 0.083535109 | AH2: =IFERROR(INDEX('Area safety'!$J$23:$J$41,MATCH($B2,'Area safety'!$A$23:$A$41,0)),"n/a") -> 1
A3: Port Edward | B3: Port Edward | C3: Available | D3: 650000 | E3: Apartment / Flat | F3: Single Storey, Top Floor | G3: 2 | H3: 1 garage | I3: 73 | J3: 2700 | K3: 1000 | L3: No | M3: Yes | N3: Urgent sale – 2-bedroom, 2-bathroom apartment in port edward! | No Pets Allowed, Fibre Internet | O3: Mandy Cope | P3: EXP South Africa | Q3: NOT CAPTURED (reCAPTCHA) | R3: NOT AVAILABLE (needs phone) | S3: Agent profile | T3: Open listing | U3: 23 September 2026 | V3: 2026-10-08 | W3: =IFERROR(INDEX('Area safety'!$C$23:$C$41,MATCH($B3,'Area safety'!$A$23:$A$41,0)),"n/a") -> Port Edward | X3: =IFERROR(INDEX('Area safety'!$D$23:$D$41,MATCH($B3,'Area safety'!$A$23:$A$41,0)),"n/a") -> CONFIRMED | Y3: =IFERROR(INDEX('Area safety'!$F$23:$F$41,MATCH($B3,'Area safety'!$A$23:$A$41,0)),"n/a") -> 571.8582 | Z3: =IFERROR(INDEX('Area safety'!$G$23:$G$41,MATCH($B3,'Area safety'!$A$23:$A$41,0)),"n/a") -> 596.91971 | AA3: =IFERROR(INDEX('Area safety'!$H$23:$H$41,MATCH($B3,'Area safety'!$A$23:$A$41,0)),"n/a") -> 27.339834 | AB3: =IFERROR(INDEX('Area safety'!$I$23:$I$41,MATCH($B3,'Area safety'!$A$23:$A$41,0)),"n/a") -> 2039.096 | AC3: =IFERROR(INDEX('Area safety'!$F$5:$F$18,MATCH($W3,'Area safety'!$A$5:$A$18,0)),"n/a") -> 895 | AD3: =IFERROR(INDEX('Area safety'!$G$5:$G$18,MATCH($W3,'Area safety'!$A$5:$A$18,0)),"n/a") -> 12 | AE3: =IFERROR(INDEX('Area safety'!$H$5:$H$18,MATCH($W3,'Area safety'!$A$5:$A$18,0)),"n/a") -> 251 | AF3: =IFERROR(INDEX('Area safety'!$I$5:$I$18,MATCH($W3,'Area safety'!$A$5:$A$18,0)),"n/a") -> 262 | AG3: =IFERROR(INDEX('Area safety'!$K$23:$K$41,MATCH($B3,'Area safety'!$A$23:$A$41,0)),"n/a") -> 0.083535109 | AH3: =IFERROR(INDEX('Area safety'!$J$23:$J$41,MATCH($B3,'Area safety'!$A$23:$A$41,0)),"n/a") -> 1
A4: Port Edward | B4: Port Edward | C4: Available | D4: 650000 | E4: Apartment / Flat | F4: NOT STATED | G4: 2 | H4: 1 garage | I4: 18 | J4: 1830 | K4: NOT STATED | L4: NOT STATED | M4: NOT STATED | N4: This charming and secure apartment is situated in a very neat and well managed complex in the coastal town of Port Edward. | Pool, Garden | O4: Annette Mentz | P4: Chas Everitt KZN South Coast | Q4: NOT CAPTURED (reCAPTCHA) | R4: NOT AVAILABLE (needs phone) | S4: Agent profile | T4: Open listing | U4: 09 June 2026 | V4: 2026-10-08 | W4: =IFERROR(INDEX('Area safety'!$C$23:$C$41,MATCH($B4,'Area safety'!$A$23:$A$41,0)),"n/a") -> Port Edward | X4: =IFERROR(INDEX('Area safety'!$D$23:$D$41,MATCH($B4,'Area safety'!$A$23:$A$41,0)),"n/a") -> CONFIRMED | Y4: =IFERROR(INDEX('Area safety'!$F$23:$F$41,MATCH($B4,'Area safety'!$A$23:$A$41,0)),"n/a") -> 571.8582 | Z4: =IFERROR(INDEX('Area safety'!$G$23:$G$41,MATCH($B4,'Area safety'!$A$23:$A$41,0)),"n/a") -> 596.91971 | AA4: =IFERROR(INDEX('Area safety'!$H$23:$H$41,MATCH($B4,'Area safety'!$A$23:$A$41,0)),"n/a") -> 27.339834 | AB4: =IFERROR(INDEX('Area safety'!$I$23:$I$41,MATCH($B4,'Area safety'!$A$23:$A$41,0)),"n/a") -> 2039.096 | AC4: =IFERROR(INDEX('Area safety'!$F$5:$F$18,MATCH($W4,'Area safety'!$A$5:$A$18,0)),"n/a") -> 895 | AD4: =IFERROR(INDEX('Area safety'!$G$5:$G$18,MATCH($W4,'Area safety'!$A$5:$A$18,0)),"n/a") -> 12 | AE4: =IFERROR(INDEX('Area safety'!$H$5:$H$18,MATCH($W4,'Area safety'!$A$5:$A$18,0)),"n/a") -> 251 | AF4: =IFERROR(INDEX('Area safety'!$I$5:$I$18,MATCH($W4,'Area safety'!$A$5:$A$18,0)),"n/a") -> 262 | AG4: =IFERROR(INDEX('Area safety'!$K$23:$K$41,MATCH($B4,'Area safety'!$A$23:$A$41,0)),"n/a") -> 0.083535109 | AH4: =IFERROR(INDEX('Area safety'!$J$23:$J$41,MATCH($B4,'Area safety'!$A$23:$A$41,0)),"n/a") -> 1
A5: Port Edward | B5: Port Edward | C5: Available | D5: 650000 | E5: Apartment / Flat | F5: Top Floor | G5: 2 | H5: 1 parking | I5: 84 | J5: 3300 | K5: 645 | L5: NOT STATED | M5: NOT STATED | N5: Escape to a peaceful coastal retreat where comfort, relaxation, and outdoor adventure come together. | Pool, Garden | O5: Tertia Sterley | P5: Property Port | Q5: NOT CAPTURED (reCAPTCHA) | R5: NOT AVAILABLE (needs phone) | S5: Agent profile | T5: Open listing | U5: 12 March 2025 | V5: 2026-10-08 | W5: =IFERROR(INDEX('Area safety'!$C$23:$C$41,MATCH($B5,'Area safety'!$A$23:$A$41,0)),"n/a") -> Port Edward | X5: =IFERROR(INDEX('Area safety'!$D$23:$D$41,MATCH($B5,'Area safety'!$A$23:$A$41,0)),"n/a") -> CONFIRMED | Y5: =IFERROR(INDEX('Area safety'!$F$23:$F$41,MATCH($B5,'Area safety'!$A$23:$A$41,0)),"n/a") -> 571.8582 | Z5: =IFERROR(INDEX('Area safety'!$G$23:$G$41,MATCH($B5,'Area safety'!$A$23:$A$41,0)),"n/a") -> 596.91971 | AA5: =IFERROR(INDEX('Area safety'!$H$23:$H$41,MATCH($B5,'Area safety'!$A$23:$A$41,0)),"n/a") -> 27.339834 | AB5: =IFERROR(INDEX('Area safety'!$I$23:$I$41,MATCH($B5,'Area safety'!$A$23:$A$41,0)),"n/a") -> 2039.096 | AC5: =IFERROR(INDEX('Area safety'!$F$5:$F$18,MATCH($W5,'Area safety'!$A$5:$A$18,0)),"n/a") -> 895 | AD5: =IFERROR(INDEX('Area safety'!$G$5:$G$18,MATCH($W5,'Area safety'!$A$5:$A$18,0)),"n/a") -> 12 | AE5: =IFERROR(INDEX('Area safety'!$H$5:$H$18,MATCH($W5,'Area safety'!$A$5:$A$18,0)),"n/a") -> 251 | AF5: =IFERROR(INDEX('Area safety'!$I$5:$I$18,MATCH($W5,'Area safety'!$A$5:$A$18,0)),"n/a") -> 262 | AG5: =IFERROR(INDEX('Area safety'!$K$23:$K$41,MATCH($B5,'Area safety'!$A$23:$A$41,0)),"n/a") -> 0.083535109 | AH5: =IFERROR(INDEX('Area safety'!$J$23:$J$41,MATCH($B5,'Area safety'!$A$23:$A$41,0)),"n/a") -> 1
A6: Port Edward | B6: Port Edward | C6: Available | D6: 650000 | E6: Apartment / Flat | F6: NOT STATED | G6: 2 | H6: NOT STATED | I6: 76 | J6: 1000 | K6: 850 | L6: NOT STATED | M6: NOT STATED | N6: A very good for investment unit be it for long term tenants or holiday letting. | Pool | O6: Cath Molyneaux | P6: Pam Golding Properties - Port Edward | Q6: NOT CAPTURED (reCAPTCHA) | R6: NOT AVAILABLE (needs phone) | S6: Agent profile | T6: Open listing | U6: 22 August 2023 | V6: 2026-10-08 | W6: =IFERROR(INDEX('Area safety'!$C$23:$C$41,MATCH($B6,'Area safety'!$A$23:$A$41,0)),"n/a") -> Port Edward | X6: =IFERROR(INDEX('Area safety'!$D$23:$D$41,MATCH($B6,'Area safety'!$A$23:$A$41,0)),"n/a") -> CONFIRMED | Y6: =IFERROR(INDEX('Area safety'!$F$23:$F$41,MATCH($B6,'Area safety'!$A$23:$A$41,0)),"n/a") -> 571.8582 | Z6: =IFERROR(INDEX('Area safety'!$G$23:$G$41,MATCH($B6,'Area safety'!$A$23:$A$41,0)),"n/a") -> 596.91971 | AA6: =IFERROR(INDEX('Area safety'!$H$23:$H$41,MATCH($B6,'Area safety'!$A$23:$A$41,0)),"n/a") -> 27.339834 | AB6: =IFERROR(INDEX('Area safety'!$I$23:$I$41,MATCH($B6,'Area safety'!$A$23:$A$41,0)),"n/a") -> 2039.096 | AC6: =IFERROR(INDEX('Area safety'!$F$5:$F$18,MATCH($W6,'Area safety'!$A$5:$A$18,0)),"n/a") -> 895 | AD6: =IFERROR(INDEX('Area safety'!$G$5:$G$18,MATCH($W6,'Area safety'!$A$5:$A$18,0)),"n/a") -> 12 | AE6: =IFERROR(INDEX('Area safety'!$H$5:$H$18,MATCH($W6,'Area safety'!$A$5:$A$18,0)),"n/a") -> 251 | AF6: =IFERROR(INDEX('Area safety'!$I$5:$I$18,MATCH($W6,'Area safety'!$A$5:$A$18,0)),"n/a") -> 262 | AG6: =IFERROR(INDEX('Area safety'!$K$23:$K$41,MATCH($B6,'Area safety'!$A$23:$A$41,0)),"n/a") -> 0.083535109 | AH6: =IFERROR(INDEX('Area safety'!$J$23:$J$41,MATCH($B6,'Area safety'!$A$23:$A$41,0)),"n/a") -> 1
A7: Port Edward | B7: Port Edward | C7: Available | D7: 654000 | E7: Apartment / Flat | F7: Second floor and above | G7: 2 | H7: NOT STATED | I7: 84 | J7: NOT STATED | K7: NOT STATED | L7: No | M7: Yes | N7: SOLE MANDATE** This fully furnished 2-bedroom flat in Port Edward is designed for comfortable coastal living. | No Pets Allowed, Fibre Internet | O7: Janine Viljoen | P7: iProperty Investment | Q7: NOT CAPTURED (reCAPTCHA) | R7: NOT AVAILABLE (needs phone) | S7: Agent profile | T7: Open listing | U7: 09 November 2024 | V7: 2026-10-08 | W7: =IFERROR(INDEX('Area safety'!$C$23:$C$41,MATCH($B7,'Area safety'!$A$23:$A$41,0)),"n/a") -> Port Edward | X7: =IFERROR(INDEX('Area safety'!$D$23:$D$41,MATCH($B7,'Area safety'!$A$23:$A$41,0)),"n/a") -> CONFIRMED | Y7: =IFERROR(INDEX('Area safety'!$F$23:$F$41,MATCH($B7,'Area safety'!$A$23:$A$41,0)),"n/a") -> 571.8582 | Z7: =IFERROR(INDEX('Area safety'!$G$23:$G$41,MATCH($B7,'Area safety'!$A$23:$A$41,0)),"n/a") -> 596.91971 | AA7: =IFERROR(INDEX('Area safety'!$H$23:$H$41,MATCH($B7,'Area safety'!$A$23:$A$41,0)),"n/a") -> 27.339834 | AB7: =IFERROR(INDEX('Area safety'!$I$23:$I$41,MATCH($B7,'Area safety'!$A$23:$A$41,0)),"n/a") -> 2039.096 | AC7: =IFERROR(INDEX('Area safety'!$F$5:$F$18,MATCH($W7,'Area safety'!$A$5:$A$18,0)),"n/a") -> 895 | AD7: =IFERROR(INDEX('Area safety'!$G$5:$G$18,MATCH($W7,'Area safety'!$A$5:$A$18,0)),"n/a") -> 12 | AE7: =IFERROR(INDEX('Area safety'!$H$5:$H$18,MATCH($W7,'Area safety'!$A$5:$A$18,0)),"n/a") -> 251 | AF7: =IFERROR(INDEX('Area safety'!$I$5:$I$18,MATCH($W7,'Area safety'!$A$5:$A$18,0)),"n/a") -> 262 | AG7: =IFERROR(INDEX('Area safety'!$K$23:$K$41,MATCH($B7,'Area safety'!$A$23:$A$41,0)),"n/a") -> 0.083535109 | AH7: =IFERROR(INDEX('Area safety'!$J$23:$J$41,MATCH($B7,'Area safety'!$A$23:$A$41,0)),"n/a") -> 1
A8: Port Edward | B8: Port Edward | C8: Available | D8: 690000 | E8: Apartment / Flat | F8: NOT STATED | G8: 2 | H8: 2 parking | I8: 84 | J8: 2375 | K8: NOT STATED | L8: NOT STATED | M8: Yes | N8: Located in the peaceful coastal area of Rennies Beach, Port Edward, this well-maintained fully furnished 2-bedroom unit offers comfortable living surr | Garden | O8: Jessica Pretorius | P8: Real & Proper T | Q8: NOT CAPTURED (reCAPTCHA) | R8: NOT AVAILABLE (needs phone) | S8: Agent profile | T8: Open listing | U8: 20 May 2026 | V8: 2026-10-08 | W8: =IFERROR(INDEX('Area safety'!$C$23:$C$41,MATCH($B8,'Area safety'!$A$23:$A$41,0)),"n/a") -> Port Edward | X8: =IFERROR(INDEX('Area safety'!$D$23:$D$41,MATCH($B8,'Area safety'!$A$23:$A$41,0)),"n/a") -> CONFIRMED | Y8: =IFERROR(INDEX('Area safety'!$F$23:$F$41,MATCH($B8,'Area safety'!$A$23:$A$41,0)),"n/a") -> 571.8582 | Z8: =IFERROR(INDEX('Area safety'!$G$23:$G$41,MATCH($B8,'Area safety'!$A$23:$A$41,0)),"n/a") -> 596.91971 | AA8: =IFERROR(INDEX('Area safety'!$H$23:$H$41,MATCH($B8,'Area safety'!$A$23:$A$41,0)),"n/a") -> 27.339834 | AB8: =IFERROR(INDEX('Area safety'!$I$23:$I$41,MATCH($B8,'Area safety'!$A$23:$A$41,0)),"n/a") -> 2039.096 | AC8: =IFERROR(INDEX('Area safety'!$F$5:$F$18,MATCH($W8,'Area safety'!$A$5:$A$18,0)),"n/a") -> 895 | AD8: =IFERROR(INDEX('Area safety'!$G$5:$G$18,MATCH($W8,'Area safety'!$A$5:$A$18,0)),"n/a") -> 12 | AE8: =IFERROR(INDEX('Area safety'!$H$5:$H$18,MATCH($W8,'Area safety'!$A$5:$A$18,0)),"n/a") -> 251 | AF8: =IFERROR(INDEX('Area safety'!$I$5:$I$18,MATCH($W8,'Area safety'!$A$5:$A$18,0)),"n/a") -> 262 | AG8: =IFERROR(INDEX('Area safety'!$K$23:$K$41,MATCH($B8,'Area safety'!$A$23:$A$41,0)),"n/a") -> 0.083535109 | AH8: =IFERROR(INDEX('Area safety'!$J$23:$J$41,MATCH($B8,'Area safety'!$A$23:$A$41,0)),"n/a") -> 1
A9: Port Edward | B9: Port Edward | C9: Available | D9: 700000 | E9: Apartment / Flat | F9: First floor (per description) | G9: 2 | H9: NOT STATED | I9: 84 | J9: NOT STATED | K9: NOT STATED | L9: NOT STATED | M9: NOT STATED | N9: A beautifully furnished first-floor apartment situated in a secure estate, offering a peaceful lifestyle surrounded by nature and beautiful views. | Pool | O9: Drienie Cilliers | P9: Pam Golding Properties - Port Edward | Q9: NOT CAPTURED (reCAPTCHA) | R9: NOT AVAILABLE (needs phone) | S9: Agent profile | T9: Open listing | U9: 09 September 2026 | V9: 2026-10-08 | W9: =IFERROR(INDEX('Area safety'!$C$23:$C$41,MATCH($B9,'Area safety'!$A$23:$A$41,0)),"n/a") -> Port Edward | X9: =IFERROR(INDEX('Area safety'!$D$23:$D$41,MATCH($B9,'Area safety'!$A$23:$A$41,0)),"n/a") -> CONFIRMED | Y9: =IFERROR(INDEX('Area safety'!$F$23:$F$41,MATCH($B9,'Area safety'!$A$23:$A$41,0)),"n/a") -> 571.8582 | Z9: =IFERROR(INDEX('Area safety'!$G$23:$G$41,MATCH($B9,'Area safety'!$A$23:$A$41,0)),"n/a") -> 596.91971 | AA9: =IFERROR(INDEX('Area safety'!$H$23:$H$41,MATCH($B9,'Area safety'!$A$23:$A$41,0)),"n/a") -> 27.339834 | AB9: =IFERROR(INDEX('Area safety'!$I$23:$I$41,MATCH($B9,'Area safety'!$A$23:$A$41,0)),"n/a") -> 2039.096 | AC9: =IFERROR(INDEX('Area safety'!$F$5:$F$18,MATCH($W9,'Area safety'!$A$5:$A$18,0)),"n/a") -> 895 | AD9: =IFERROR(INDEX('Area safety'!$G$5:$G$18,MATCH($W9,'Area safety'!$A$5:$A$18,0)),"n/a") -> 12 | AE9: =IFERROR(INDEX('Area safety'!$H$5:$H$18,MATCH($W9,'Area safety'!$A$5:$A$18,0)),"n/a") -> 251 | AF9: =IFERROR(INDEX('Area safety'!$I$5:$I$18,MATCH($W9,'Area safety'!$A$5:$A$18,0)),"n/a") -> 262 | AG9: =IFERROR(INDEX('Area safety'!$K$23:$K$41,MATCH($B9,'Area safety'!$A$23:$A$41,0)),"n/a") -> 0.083535109 | AH9: =IFERROR(INDEX('Area safety'!$J$23:$J$41,MATCH($B9,'Area safety'!$A$23:$A$41,0)),"n/a") -> 1
A10: Port Edward | B10: Port Edward | C10: Available | D10: 700000 | E10: Apartment / Flat | F10: First Floor | G10: 2 | H10: 1 parking | I10: 84 | J10: 2500 | K10: 550 | L10: No | M10: NOT STATED | N10: SOLE MANDATE *** Nestled on the banks of the Umtamvuna river and surrounded by the serene beauty of nature, this upmarket and exclusive two-bedroom, o | No Pets Allowed, Pool, Garden | O10: Angelique Marran | P10: RE/MAX Coast and Country Southbroom | Q10: NOT CAPTURED (reCAPTCHA) | R10: NOT AVAILABLE (needs phone) | S10: Agent profile | T10: Open listing | U10: 13 October 2024 | V10: 2026-10-08 | W10: =IFERROR(INDEX('Area safety'!$C$23:$C$41,MATCH($B10,'Area safety'!$A$23:$A$41,0)),"n/a") -> Port Edward | X10: =IFERROR(INDEX('Area safety'!$D$23:$D$41,MATCH($B10,'Area safety'!$A$23:$A$41,0)),"n/a") -> CONFIRMED | Y10: =IFERROR(INDEX('Area safety'!$F$23:$F$41,MATCH($B10,'Area safety'!$A$23:$A$41,0)),"n/a") -> 571.8582 | Z10: =IFERROR(INDEX('Area safety'!$G$23:$G$41,MATCH($B10,'Area safety'!$A$23:$A$41,0)),"n/a") -> 596.91971 | AA10: =IFERROR(INDEX('Area safety'!$H$23:$H$41,MATCH($B10,'Area safety'!$A$23:$A$41,0)),"n/a") -> 27.339834 | AB10: =IFERROR(INDEX('Area safety'!$I$23:$I$41,MATCH($B10,'Area safety'!$A$23:$A$41,0)),"n/a") -> 2039.096 | AC10: =IFERROR(INDEX('Area safety'!$F$5:$F$18,MATCH($W10,'Area safety'!$A$5:$A$18,0)),"n/a") -> 895 | AD10: =IFERROR(INDEX('Area safety'!$G$5:$G$18,MATCH($W10,'Area safety'!$A$5:$A$18,0)),"n/a") -> 12 | AE10: =IFERROR(INDEX('Area safety'!$H$5:$H$18,MATCH($W10,'Area safety'!$A$5:$A$18,0)),"n/a") -> 251 | AF10: =IFERROR(INDEX('Area safety'!$I$5:$I$18,MATCH($W10,'Area safety'!$A$5:$A$18,0)),"n/a") -> 262 | AG10: =IFERROR(INDEX('Area safety'!$K$23:$K$41,MATCH($B10,'Area safety'!$A$23:$A$41,0)),"n/a") -> 0.083535109 | AH10: =IFERROR(INDEX('Area safety'!$J$23:$J$41,MATCH($B10,'Area safety'!$A$23:$A$41,0)),"n/a") -> 1
A11: Port Edward | B11: Port Edward | C11: Available | D11: 720000 | E11: Apartment / Flat | F11: NOT STATED | G11: 2 | H11: 1 garage | I11: 111 | J11: 1895 | K11: 800 | L11: Yes | M11: NOT STATED | N11: Lovely 2 bedroom duplex unit situated in a very secure complex close to all major amenities. | Pet Friendly, Pool, Garden, Fibre Internet | O11: Jean Du Toit | P11: Shoreline Properties Leisure Bay | Q11: NOT CAPTURED (reCAPTCHA) | R11: NOT AVAILABLE (needs phone) | S11: Agent profile | T11: Open listing | U11: 12 September 2024 | V11: 2026-10-08 | W11: =IFERROR(INDEX('Area safety'!$C$23:$C$41,MATCH($B11,'Area safety'!$A$23:$A$41,0)),"n/a") -> Port Edward | X11: =IFERROR(INDEX('Area safety'!$D$23:$D$41,MATCH($B11,'Area safety'!$A$23:$A$41,0)),"n/a") -> CONFIRMED | Y11: =IFERROR(INDEX('Area safety'!$F$23:$F$41,MATCH($B11,'Area safety'!$A$23:$A$41,0)),"n/a") -> 571.8582 | Z11: =IFERROR(INDEX('Area safety'!$G$23:$G$41,MATCH($B11,'Area safety'!$A$23:$A$41,0)),"n/a") -> 596.91971 | AA11: =IFERROR(INDEX('Area safety'!$H$23:$H$41,MATCH($B11,'Area safety'!$A$23:$A$41,0)),"n/a") -> 27.339834 | AB11: =IFERROR(INDEX('Area safety'!$I$23:$I$41,MATCH($B11,'Area safety'!$A$23:$A$41,0)),"n/a") -> 2039.096 | AC11: =IFERROR(INDEX('Area safety'!$F$5:$F$18,MATCH($W11,'Area safety'!$A$5:$A$18,0)),"n/a") -> 895 | AD11: =IFERROR(INDEX('Area safety'!$G$5:$G$18,MATCH($W11,'Area safety'!$A$5:$A$18,0)),"n/a") -> 12 | AE11: =IFERROR(INDEX('Area safety'!$H$5:$H$18,MATCH($W11,'Area safety'!$A$5:$A$18,0)),"n/a") -> 251 | AF11: =IFERROR(INDEX('Area safety'!$I$5:$I$18,MATCH($W11,'Area safety'!$A$5:$A$18,0)),"n/a") -> 262 | AG11: =IFERROR(INDEX('Area safety'!$K$23:$K$41,MATCH($B11,'Area safety'!$A$23:$A$41,0)),"n/a") -> 0.083535109 | AH11: =IFERROR(INDEX('Area safety'!$J$23:$J$41,MATCH($B11,'Area safety'!$A$23:$A$41,0)),"n/a") -> 1
A12: Port Edward | B12: Glenmore | C12: Available | D12: 620000 | E12: Apartment / Flat | F12: NOT STATED | G12: 2 | H12: 1 parking | I12: 85 | J12: 2200 | K12: 650 | L12: Yes | M12: NOT STATED | N12: Ideal 2 Bedroom Retirement/Holiday unit in secure complex close to all amenities. | Pet Friendly, Pool, Garden, Fibre Internet | O12: NOT STATED | P12: Realty1 Munster | Q12: NOT CAPTURED (reCAPTCHA) | R12: NOT AVAILABLE (needs phone) | S12: NOT STATED | T12: Open listing | U12: 20 July 2026 | V12: 2026-10-08 | W12: =IFERROR(INDEX('Area safety'!$C$23:$C$41,MATCH($B12,'Area safety'!$A$23:$A$41,0)),"n/a") -> Port Edward | X12: =IFERROR(INDEX('Area safety'!$D$23:$D$41,MATCH($B12,'Area safety'!$A$23:$A$41,0)),"n/a") -> UNCONFIRMED - provisional (assumed Port Edward precinct) | Y12: =IFERROR(INDEX('Area safety'!$F$23:$F$41,MATCH($B12,'Area safety'!$A$23:$A$41,0)),"n/a") -> 571.8582 | Z12: =IFERROR(INDEX('Area safety'!$G$23:$G$41,MATCH($B12,'Area safety'!$A$23:$A$41,0)),"n/a") -> 596.91971 | AA12: =IFERROR(INDEX('Area safety'!$H$23:$H$41,MATCH($B12,'Area safety'!$A$23:$A$41,0)),"n/a") -> 27.339834 | AB12: =IFERROR(INDEX('Area safety'!$I$23:$I$41,MATCH($B12,'Area safety'!$A$23:$A$41,0)),"n/a") -> 2039.096 | AC12: =IFERROR(INDEX('Area safety'!$F$5:$F$18,MATCH($W12,'Area safety'!$A$5:$A$18,0)),"n/a") -> 895 | AD12: =IFERROR(INDEX('Area safety'!$G$5:$G$18,MATCH($W12,'Area safety'!$A$5:$A$18,0)),"n/a") -> 12 | AE12: =IFERROR(INDEX('Area safety'!$H$5:$H$18,MATCH($W12,'Area safety'!$A$5:$A$18,0)),"n/a") -> 251 | AF12: =IFERROR(INDEX('Area safety'!$I$5:$I$18,MATCH($W12,'Area safety'!$A$5:$A$18,0)),"n/a") -> 262 | AG12: =IFERROR(INDEX('Area safety'!$K$23:$K$41,MATCH($B12,'Area safety'!$A$23:$A$41,0)),"n/a") -> 0.083535109 | AH12: =IFERROR(INDEX('Area safety'!$J$23:$J$41,MATCH($B12,'Area safety'!$A$23:$A$41,0)),"n/a") -> 1
A13: Port Edward | B13: Glenmore | C13: Available | D13: 620000 | E13: Apartment / Flat | F13: NOT STATED | G13: 2 | H13: 2 parking | I13: 85 | J13: 2200 | K13: 700 | L13: Yes | M13: NOT STATED | N13: Priced to sell fast! This neat and spacious 2-bedroom, 1-bathroom unit is perfect for retirees or holidaymakers looking for comfort and convenience. | Pet Friendly, Pool | O13: Keith Roger Nkala | P13: EXP South Africa | Q13: NOT CAPTURED (reCAPTCHA) | R13: NOT AVAILABLE (needs phone) | S13: Agent profile | T13: Open listing | U13: 22 July 2026 | V13: 2026-10-08 | W13: =IFERROR(INDEX('Area safety'!$C$23:$C$41,MATCH($B13,'Area safety'!$A$23:$A$41,0)),"n/a") -> Port Edward | X13: =IFERROR(INDEX('Area safety'!$D$23:$D$41,MATCH($B13,'Area safety'!$A$23:$A$41,0)),"n/a") -> UNCONFIRMED - provisional (assumed Port Edward precinct) | Y13: =IFERROR(INDEX('Area safety'!$F$23:$F$41,MATCH($B13,'Area safety'!$A$23:$A$41,0)),"n/a") -> 571.8582 | Z13: =IFERROR(INDEX('Area safety'!$G$23:$G$41,MATCH($B13,'Area safety'!$A$23:$A$41,0)),"n/a") -> 596.91971 | AA13: =IFERROR(INDEX('Area safety'!$H$23:$H$41,MATCH($B13,'Area safety'!$A$23:$A$41,0)),"n/a") -> 27.339834 | AB13: =IFERROR(INDEX('Area safety'!$I$23:$I$41,MATCH($B13,'Area safety'!$A$23:$A$41,0)),"n/a") -> 2039.096 | AC13: =IFERROR(INDEX('Area safety'!$F$5:$F$18,MATCH($W13,'Area safety'!$A$5:$A$18,0)),"n/a") -> 895 | AD13: =IFERROR(INDEX('Area safety'!$G$5:$G$18,MATCH($W13,'Area safety'!$A$5:$A$18,0)),"n/a") -> 12 | AE13: =IFERROR(INDEX('Area safety'!$H$5:$H$18,MATCH($W13,'Area safety'!$A$5:$A$18,0)),"n/a") -> 251 | AF13: =IFERROR(INDEX('Area safety'!$I$5:$I$18,MATCH($W13,'Area safety'!$A$5:$A$18,0)),"n/a") -> 262 | AG13: =IFERROR(INDEX('Area safety'!$K$23:$K$41,MATCH($B13,'Area safety'!$A$23:$A$41,0)),"n/a") -> 0.083535109 | AH13: =IFERROR(INDEX('Area safety'!$J$23:$J$41,MATCH($B13,'Area safety'!$A$23:$A$41,0)),"n/a") -> 1
A14: Port Edward | B14: Glenmore | C14: Available | D14: 650000 | E14: Apartment / Flat | F14: First floor (per description) | G14: 2 | H14: 1 parking | I14: 60 | J14: 1600 | K14: 850 | L14: NOT STATED | M14: NOT STATED | N14: Charming Coastal Apartment in a Peaceful Setting Enjoy comfortable coastal living in this lovely apartment, situated within a short walking distance o | Pool, Garden | O14: Sylvia Mc Donald | P14: Real Estate Services | Q14: NOT CAPTURED (reCAPTCHA) | R14: NOT AVAILABLE (needs phone) | S14: Agent profile | T14: Open listing | U14: 04 September 2026 | V14: 2026-10-08 | W14: =IFERROR(INDEX('Area safety'!$C$23:$C$41,MATCH($B14,'Area safety'!$A$23:$A$41,0)),"n/a") -> Port Edward | X14: =IFERROR(INDEX('Area safety'!$D$23:$D$41,MATCH($B14,'Area safety'!$A$23:$A$41,0)),"n/a") -> UNCONFIRMED - provisional (assumed Port Edward precinct) | Y14: =IFERROR(INDEX('Area safety'!$F$23:$F$41,MATCH($B14,'Area safety'!$A$23:$A$41,0)),"n/a") -> 571.8582 | Z14: =IFERROR(INDEX('Area safety'!$G$23:$G$41,MATCH($B14,'Area safety'!$A$23:$A$41,0)),"n/a") -> 596.91971 | AA14: =IFERROR(INDEX('Area safety'!$H$23:$H$41,MATCH($B14,'Area safety'!$A$23:$A$41,0)),"n/a") -> 27.339834 | AB14: =IFERROR(INDEX('Area safety'!$I$23:$I$41,MATCH($B14,'Area safety'!$A$23:$A$41,0)),"n/a") -> 2039.096 | AC14: =IFERROR(INDEX('Area safety'!$F$5:$F$18,MATCH($W14,'Area safety'!$A$5:$A$18,0)),"n/a") -> 895 | AD14: =IFERROR(INDEX('Area safety'!$G$5:$G$18,MATCH($W14,'Area safety'!$A$5:$A$18,0)),"n/a") -> 12 | AE14: =IFERROR(INDEX('Area safety'!$H$5:$H$18,MATCH($W14,'Area safety'!$A$5:$A$18,0)),"n/a") -> 251 | AF14: =IFERROR(INDEX('Area safety'!$I$5:$I$18,MATCH($W14,'Area safety'!$A$5:$A$18,0)),"n/a") -> 262 | AG14: =IFERROR(INDEX('Area safety'!$K$23:$K$41,MATCH($B14,'Area safety'!$A$23:$A$41,0)),"n/a") -> 0.083535109 | AH14: =IFERROR(INDEX('Area safety'!$J$23:$J$41,MATCH($B14,'Area safety'!$A$23:$A$41,0)),"n/a") -> 1
A15: Port Edward | B15: Glenmore | C15: Available | D15: 695000 | E15: Apartment / Flat | F15: Mixed: description mentions ground AND second floor [CHECK floor] | G15: 2 | H15: 1 parking | I15: 58 | J15: 2000 | K15: 450 | L15: No | M15: Yes | N15: Prime investment opportunities like this don't come around too often. | No Pets Allowed, Pool, Solar Panels | O15: NOT STATED | P15: Realty1 Munster | Q15: NOT CAPTURED (reCAPTCHA) | R15: NOT AVAILABLE (needs phone) | S15: NOT STATED | T15: Open listing | U15: 23 September 2026 | V15: 2026-10-08 | W15: =IFERROR(INDEX('Area safety'!$C$23:$C$41,MATCH($B15,'Area safety'!$A$23:$A$41,0)),"n/a") -> Port Edward | X15: =IFERROR(INDEX('Area safety'!$D$23:$D$41,MATCH($B15,'Area safety'!$A$23:$A$41,0)),"n/a") -> UNCONFIRMED - provisional (assumed Port Edward precinct) | Y15: =IFERROR(INDEX('Area safety'!$F$23:$F$41,MATCH($B15,'Area safety'!$A$23:$A$41,0)),"n/a") -> 571.8582 | Z15: =IFERROR(INDEX('Area safety'!$G$23:$G$41,MATCH($B15,'Area safety'!$A$23:$A$41,0)),"n/a") -> 596.91971 | AA15: =IFERROR(INDEX('Area safety'!$H$23:$H$41,MATCH($B15,'Area safety'!$A$23:$A$41,0)),"n/a") -> 27.339834 | AB15: =IFERROR(INDEX('Area safety'!$I$23:$I$41,MATCH($B15,'Area safety'!$A$23:$A$41,0)),"n/a") -> 2039.096 | AC15: =IFERROR(INDEX('Area safety'!$F$5:$F$18,MATCH($W15,'Area safety'!$A$5:$A$18,0)),"n/a") -> 895 | AD15: =IFERROR(INDEX('Area safety'!$G$5:$G$18,MATCH($W15,'Area safety'!$A$5:$A$18,0)),"n/a") -> 12 | AE15: =IFERROR(INDEX('Area safety'!$H$5:$H$18,MATCH($W15,'Area safety'!$A$5:$A$18,0)),"n/a") -> 251 | AF15: =IFERROR(INDEX('Area safety'!$I$5:$I$18,MATCH($W15,'Area safety'!$A$5:$A$18,0)),"n/a") -> 262 | AG15: =IFERROR(INDEX('Area safety'!$K$23:$K$41,MATCH($B15,'Area safety'!$A$23:$A$41,0)),"n/a") -> 0.083535109 | AH15: =IFERROR(INDEX('Area safety'!$J$23:$J$41,MATCH($B15,'Area safety'!$A$23:$A$41,0)),"n/a") -> 1
A16: Port Edward | B16: Glenmore | C16: Available | D16: 695000 | E16: Apartment / Flat | F16: Floor 1 | G16: 2 | H16: 1 parking | I16: 74 | J16: 2133 | K16: 1200 | L16: No | M16: NOT STATED | N16: This well-positioned 2-bedroom apartment offers comfortable and secure living, ideal for both homeowners and investors. | No Pets Allowed | O16: Snyanie Tshobonga | P16: Just Property Living | Q16: NOT CAPTURED (reCAPTCHA) | R16: NOT AVAILABLE (needs phone) | S16: Agent profile | T16: Open listing | U16: 08 April 2026 | V16: 2026-10-08 | W16: =IFERROR(INDEX('Area safety'!$C$23:$C$41,MATCH($B16,'Area safety'!$A$23:$A$41,0)),"n/a") -> Port Edward | X16: =IFERROR(INDEX('Area safety'!$D$23:$D$41,MATCH($B16,'Area safety'!$A$23:$A$41,0)),"n/a") -> UNCONFIRMED - provisional (assumed Port Edward precinct) | Y16: =IFERROR(INDEX('Area safety'!$F$23:$F$41,MATCH($B16,'Area safety'!$A$23:$A$41,0)),"n/a") -> 571.8582 | Z16: =IFERROR(INDEX('Area safety'!$G$23:$G$41,MATCH($B16,'Area safety'!$A$23:$A$41,0)),"n/a") -> 596.91971 | AA16: =IFERROR(INDEX('Area safety'!$H$23:$H$41,MATCH($B16,'Area safety'!$A$23:$A$41,0)),"n/a") -> 27.339834 | AB16: =IFERROR(INDEX('Area safety'!$I$23:$I$41,MATCH($B16,'Area safety'!$A$23:$A$41,0)),"n/a") -> 2039.096 | AC16: =IFERROR(INDEX('Area safety'!$F$5:$F$18,MATCH($W16,'Area safety'!$A$5:$A$18,0)),"n/a") -> 895 | AD16: =IFERROR(INDEX('Area safety'!$G$5:$G$18,MATCH($W16,'Area safety'!$A$5:$A$18,0)),"n/a") -> 12 | AE16: =IFERROR(INDEX('Area safety'!$H$5:$H$18,MATCH($W16,'Area safety'!$A$5:$A$18,0)),"n/a") -> 251 | AF16: =IFERROR(INDEX('Area safety'!$I$5:$I$18,MATCH($W16,'Area safety'!$A$5:$A$18,0)),"n/a") -> 262 | AG16: =IFERROR(INDEX('Area safety'!$K$23:$K$41,MATCH($B16,'Area safety'!$A$23:$A$41,0)),"n/a") -> 0.083535109 | AH16: =IFERROR(INDEX('Area safety'!$J$23:$J$41,MATCH($B16,'Area safety'!$A$23:$A$41,0)),"n/a") -> 1
A17: Port Edward | B17: Glenmore | C17: Available | D17: 750000 | E17: Apartment / Flat | F17: NOT STATED | G17: 2 | H17: 1 parking | I17: NOT STATED | J17: 1700 | K17: 750 | L17: Yes | M17: Yes | N17: Have you been dreaming of living on the south coast. | Pet Friendly, Pool, Garden | O17: Annette Mentz | P17: Chas Everitt KZN South Coast | Q17: NOT CAPTURED (reCAPTCHA) | R17: NOT AVAILABLE (needs phone) | S17: Agent profile | T17: Open listing | U17: 04 July 2023 | V17: 2026-10-08 | W17: =IFERROR(INDEX('Area safety'!$C$23:$C$41,MATCH($B17,'Area safety'!$A$23:$A$41,0)),"n/a") -> Port Edward | X17: =IFERROR(INDEX('Area safety'!$D$23:$D$41,MATCH($B17,'Area safety'!$A$23:$A$41,0)),"n/a") -> UNCONFIRMED - provisional (assumed Port Edward precinct) | Y17: =IFERROR(INDEX('Area safety'!$F$23:$F$41,MATCH($B17,'Area safety'!$A$23:$A$41,0)),"n/a") -> 571.8582 | Z17: =IFERROR(INDEX('Area safety'!$G$23:$G$41,MATCH($B17,'Area safety'!$A$23:$A$41,0)),"n/a") -> 596.91971 | AA17: =IFERROR(INDEX('Area safety'!$H$23:$H$41,MATCH($B17,'Area safety'!$A$23:$A$41,0)),"n/a") -> 27.339834 | AB17: =IFERROR(INDEX('Area safety'!$I$23:$I$41,MATCH($B17,'Area safety'!$A$23:$A$41,0)),"n/a") -> 2039.096 | AC17: =IFERROR(INDEX('Area safety'!$F$5:$F$18,MATCH($W17,'Area safety'!$A$5:$A$18,0)),"n/a") -> 895 | AD17: =IFERROR(INDEX('Area safety'!$G$5:$G$18,MATCH($W17,'Area safety'!$A$5:$A$18,0)),"n/a") -> 12 | AE17: =IFERROR(INDEX('Area safety'!$H$5:$H$18,MATCH($W17,'Area safety'!$A$5:$A$18,0)),"n/a") -> 251 | AF17: =IFERROR(INDEX('Area safety'!$I$5:$I$18,MATCH($W17,'Area safety'!$A$5:$A$18,0)),"n/a") -> 262 | AG17: =IFERROR(INDEX('Area safety'!$K$23:$K$41,MATCH($B17,'Area safety'!$A$23:$A$41,0)),"n/a") -> 0.083535109 | AH17: =IFERROR(INDEX('Area safety'!$J$23:$J$41,MATCH($B17,'Area safety'!$A$23:$A$41,0)),"n/a") -> 1
A18: Port Edward | B18: Leisure Bay | C18: Available | D18: 570000 | E18: Apartment / Flat | F18: NOT STATED | G18: 2 | H18: 1 parking | I18: 83 | J18: NOT STATED | K18: NOT STATED | L18: NOT STATED | M18: NOT STATED | N18: Hello, my name is Steven, your dedicated South Coast Property Practitioner. | O18: Steven Plint | P18: Real & Proper T | Q18: NOT CAPTURED (reCAPTCHA) | R18: NOT AVAILABLE (needs phone) | S18: Agent profile | T18: Open listing | U18: 01 July 2026 | V18: 2026-10-08 | W18: =IFERROR(INDEX('Area safety'!$C$23:$C$41,MATCH($B18,'Area safety'!$A$23:$A$41,0)),"n/a") -> Port Edward | X18: =IFERROR(INDEX('Area safety'!$D$23:$D$41,MATCH($B18,'Area safety'!$A$23:$A$41,0)),"n/a") -> CONFIRMED | Y18: =IFERROR(INDEX('Area safety'!$F$23:$F$41,MATCH($B18,'Area safety'!$A$23:$A$41,0)),"n/a") -> 571.8582 | Z18: =IFERROR(INDEX('Area safety'!$G$23:$G$41,MATCH($B18,'Area safety'!$A$23:$A$41,0)),"n/a") -> 596.91971 | AA18: =IFERROR(INDEX('Area safety'!$H$23:$H$41,MATCH($B18,'Area safety'!$A$23:$A$41,0)),"n/a") -> 27.339834 | AB18: =IFERROR(INDEX('Area safety'!$I$23:$I$41,MATCH($B18,'Area safety'!$A$23:$A$41,0)),"n/a") -> 2039.096 | AC18: =IFERROR(INDEX('Area safety'!$F$5:$F$18,MATCH($W18,'Area safety'!$A$5:$A$18,0)),"n/a") -> 895 | AD18: =IFERROR(INDEX('Area safety'!$G$5:$G$18,MATCH($W18,'Area safety'!$A$5:$A$18,0)),"n/a") -> 12 | AE18: =IFERROR(INDEX('Area safety'!$H$5:$H$18,MATCH($W18,'Area safety'!$A$5:$A$18,0)),"n/a") -> 251 | AF18: =IFERROR(INDEX('Area safety'!$I$5:$I$18,MATCH($W18,'Area safety'!$A$5:$A$18,0)),"n/a") -> 262 | AG18: =IFERROR(INDEX('Area safety'!$K$23:$K$41,MATCH($B18,'Area safety'!$A$23:$A$41,0)),"n/a") -> 0.083535109 | AH18: =IFERROR(INDEX('Area safety'!$J$23:$J$41,MATCH($B18,'Area safety'!$A$23:$A$41,0)),"n/a") -> 1
A19: Port Edward | B19: Leisure Bay | C19: Available | D19: 695000 | E19: Apartment / Flat | F19: NOT STATED | G19: 2 | H19: 1 parking | I19: 78 | J19: 3000 | K19: 700 | L19: No | M19: Optional | N19: Leisure Bay If you are looking for a neat and well run complex on the coast, then this is it!! | No Pets Allowed, Fibre Internet | O19: Jean Du Toit | P19: Shoreline Properties Leisure Bay | Q19: NOT CAPTURED (reCAPTCHA) | R19: NOT AVAILABLE (needs phone) | S19: Agent profile | T19: Open listing | U19: 16 April 2026 | V19: 2026-10-08 | W19: =IFERROR(INDEX('Area safety'!$C$23:$C$41,MATCH($B19,'Area safety'!$A$23:$A$41,0)),"n/a") -> Port Edward | X19: =IFERROR(INDEX('Area safety'!$D$23:$D$41,MATCH($B19,'Area safety'!$A$23:$A$41,0)),"n/a") -> CONFIRMED | Y19: =IFERROR(INDEX('Area safety'!$F$23:$F$41,MATCH($B19,'Area safety'!$A$23:$A$41,0)),"n/a") -> 571.8582 | Z19: =IFERROR(INDEX('Area safety'!$G$23:$G$41,MATCH($B19,'Area safety'!$A$23:$A$41,0)),"n/a") -> 596.91971 | AA19: =IFERROR(INDEX('Area safety'!$H$23:$H$41,MATCH($B19,'Area safety'!$A$23:$A$41,0)),"n/a") -> 27.339834 | AB19: =IFERROR(INDEX('Area safety'!$I$23:$I$41,MATCH($B19,'Area safety'!$A$23:$A$41,0)),"n/a") -> 2039.096 | AC19: =IFERROR(INDEX('Area safety'!$F$5:$F$18,MATCH($W19,'Area safety'!$A$5:$A$18,0)),"n/a") -> 895 | AD19: =IFERROR(INDEX('Area safety'!$G$5:$G$18,MATCH($W19,'Area safety'!$A$5:$A$18,0)),"n/a") -> 12 | AE19: =IFERROR(INDEX('Area safety'!$H$5:$H$18,MATCH($W19,'Area safety'!$A$5:$A$18,0)),"n/a") -> 251 | AF19: =IFERROR(INDEX('Area safety'!$I$5:$I$18,MATCH($W19,'Area safety'!$A$5:$A$18,0)),"n/a") -> 262 | AG19: =IFERROR(INDEX('Area safety'!$K$23:$K$41,MATCH($B19,'Area safety'!$A$23:$A$41,0)),"n/a") -> 0.083535109 | AH19: =IFERROR(INDEX('Area safety'!$J$23:$J$41,MATCH($B19,'Area safety'!$A$23:$A$41,0)),"n/a") -> 1
A20: Port Edward | B20: Banners Rest | C20: Available | D20: 540000 | E20: Apartment / Flat | F20: NOT STATED | G20: 2 | H20: NOT STATED | I20: 86 | J20: 1727 | K20: NOT STATED | L20: NOT STATED | M20: NOT STATED | N20: Experience the ultimate blend of natural beauty and modern comfort in this stunning 2-bedroom apartment. | Pool | O20: Drienie Cilliers | P20: Pam Golding Properties - Port Edward | Q20: NOT CAPTURED (reCAPTCHA) | R20: NOT AVAILABLE (needs phone) | S20: Agent profile | T20: Open listing | U20: 30 October 2024 | V20: 2026-10-08 | W20: =IFERROR(INDEX('Area safety'!$C$23:$C$41,MATCH($B20,'Area safety'!$A$23:$A$41,0)),"n/a") -> Port Edward | X20: =IFERROR(INDEX('Area safety'!$D$23:$D$41,MATCH($B20,'Area safety'!$A$23:$A$41,0)),"n/a") -> UNCONFIRMED - provisional (assumed Port Edward precinct) | Y20: =IFERROR(INDEX('Area safety'!$F$23:$F$41,MATCH($B20,'Area safety'!$A$23:$A$41,0)),"n/a") -> 571.8582 | Z20: =IFERROR(INDEX('Area safety'!$G$23:$G$41,MATCH($B20,'Area safety'!$A$23:$A$41,0)),"n/a") -> 596.91971 | AA20: =IFERROR(INDEX('Area safety'!$H$23:$H$41,MATCH($B20,'Area safety'!$A$23:$A$41,0)),"n/a") -> 27.339834 | AB20: =IFERROR(INDEX('Area safety'!$I$23:$I$41,MATCH($B20,'Area safety'!$A$23:$A$41,0)),"n/a") -> 2039.096 | AC20: =IFERROR(INDEX('Area safety'!$F$5:$F$18,MATCH($W20,'Area safety'!$A$5:$A$18,0)),"n/a") -> 895 | AD20: =IFERROR(INDEX('Area safety'!$G$5:$G$18,MATCH($W20,'Area safety'!$A$5:$A$18,0)),"n/a") -> 12 | AE20: =IFERROR(INDEX('Area safety'!$H$5:$H$18,MATCH($W20,'Area safety'!$A$5:$A$18,0)),"n/a") -> 251 | AF20: =IFERROR(INDEX('Area safety'!$I$5:$I$18,MATCH($W20,'Area safety'!$A$5:$A$18,0)),"n/a") -> 262 | AG20: =IFERROR(INDEX('Area safety'!$K$23:$K$41,MATCH($B20,'Area safety'!$A$23:$A$41,0)),"n/a") -> 0.083535109 | AH20: =IFERROR(INDEX('Area safety'!$J$23:$J$41,MATCH($B20,'Area safety'!$A$23:$A$41,0)),"n/a") -> 1
A21: Port Edward | B21: Banners Rest | C21: Available | D21: 545000 | E21: Apartment / Flat | F21: NOT STATED | G21: 2 | H21: 1 garage | I21: 86 | J21: 2765 | K21: 800 | L21: NOT STATED | M21: NOT STATED | N21: Discover relaxed coastal living in this beautiful 2-bedroom apartment perfectly positioned in the sought-after Banners Rest area. | Pool | O21: Cath Molyneaux | P21: Pam Golding Properties - Port Edward | Q21: NOT CAPTURED (reCAPTCHA) | R21: NOT AVAILABLE (needs phone) | S21: Agent profile | T21: Open listing | U21: 14 November 2025 | V21: 2026-10-08 | W21: =IFERROR(INDEX('Area safety'!$C$23:$C$41,MATCH($B21,'Area safety'!$A$23:$A$41,0)),"n/a") -> Port Edward | X21: =IFERROR(INDEX('Area safety'!$D$23:$D$41,MATCH($B21,'Area safety'!$A$23:$A$41,0)),"n/a") -> UNCONFIRMED - provisional (assumed Port Edward precinct) | Y21: =IFERROR(INDEX('Area safety'!$F$23:$F$41,MATCH($B21,'Area safety'!$A$23:$A$41,0)),"n/a") -> 571.8582 | Z21: =IFERROR(INDEX('Area safety'!$G$23:$G$41,MATCH($B21,'Area safety'!$A$23:$A$41,0)),"n/a") -> 596.91971 | AA21: =IFERROR(INDEX('Area safety'!$H$23:$H$41,MATCH($B21,'Area safety'!$A$23:$A$41,0)),"n/a") -> 27.339834 | AB21: =IFERROR(INDEX('Area safety'!$I$23:$I$41,MATCH($B21,'Area safety'!$A$23:$A$41,0)),"n/a") -> 2039.096 | AC21: =IFERROR(INDEX('Area safety'!$F$5:$F$18,MATCH($W21,'Area safety'!$A$5:$A$18,0)),"n/a") -> 895 | AD21: =IFERROR(INDEX('Area safety'!$G$5:$G$18,MATCH($W21,'Area safety'!$A$5:$A$18,0)),"n/a") -> 12 | AE21: =IFERROR(INDEX('Area safety'!$H$5:$H$18,MATCH($W21,'Area safety'!$A$5:$A$18,0)),"n/a") -> 251 | AF21: =IFERROR(INDEX('Area safety'!$I$5:$I$18,MATCH($W21,'Area safety'!$A$5:$A$18,0)),"n/a") -> 262 | AG21: =IFERROR(INDEX('Area safety'!$K$23:$K$41,MATCH($B21,'Area safety'!$A$23:$A$41,0)),"n/a") -> 0.083535109 | AH21: =IFERROR(INDEX('Area safety'!$J$23:$J$41,MATCH($B21,'Area safety'!$A$23:$A$41,0)),"n/a") -> 1
A22: Port Edward | B22: Banners Rest | C22: Available | D22: 550000 | E22: Apartment / Flat | F22: NOT STATED | G22: 2 | H22: 2 parking | I22: 84 | J22: 2300 | K22: 600 | L22: NOT STATED | M22: NOT STATED | N22: Discover an irresistible offer! | Pool | O22: Dennis Hammerschlag | P22: Pam Golding Properties - Port Edward | Q22: NOT CAPTURED (reCAPTCHA) | R22: NOT AVAILABLE (needs phone) | S22: Agent profile | T22: Open listing | U22: 04 June 2025 | V22: 2026-10-08 | W22: =IFERROR(INDEX('Area safety'!$C$23:$C$41,MATCH($B22,'Area safety'!$A$23:$A$41,0)),"n/a") -> Port Edward | X22: =IFERROR(INDEX('Area safety'!$D$23:$D$41,MATCH($B22,'Area safety'!$A$23:$A$41,0)),"n/a") -> UNCONFIRMED - provisional (assumed Port Edward precinct) | Y22: =IFERROR(INDEX('Area safety'!$F$23:$F$41,MATCH($B22,'Area safety'!$A$23:$A$41,0)),"n/a") -> 571.8582 | Z22: =IFERROR(INDEX('Area safety'!$G$23:$G$41,MATCH($B22,'Area safety'!$A$23:$A$41,0)),"n/a") -> 596.91971 | AA22: =IFERROR(INDEX('Area safety'!$H$23:$H$41,MATCH($B22,'Area safety'!$A$23:$A$41,0)),"n/a") -> 27.339834 | AB22: =IFERROR(INDEX('Area safety'!$I$23:$I$41,MATCH($B22,'Area safety'!$A$23:$A$41,0)),"n/a") -> 2039.096 | AC22: =IFERROR(INDEX('Area safety'!$F$5:$F$18,MATCH($W22,'Area safety'!$A$5:$A$18,0)),"n/a") -> 895 | AD22: =IFERROR(INDEX('Area safety'!$G$5:$G$18,MATCH($W22,'Area safety'!$A$5:$A$18,0)),"n/a") -> 12 | AE22: =IFERROR(INDEX('Area safety'!$H$5:$H$18,MATCH($W22,'Area safety'!$A$5:$A$18,0)),"n/a") -> 251 | AF22: =IFERROR(INDEX('Area safety'!$I$5:$I$18,MATCH($W22,'Area safety'!$A$5:$A$18,0)),"n/a") -> 262 | AG22: =IFERROR(INDEX('Area safety'!$K$23:$K$41,MATCH($B22,'Area safety'!$A$23:$A$41,0)),"n/a") -> 0.083535109 | AH22: =IFERROR(INDEX('Area safety'!$J$23:$J$41,MATCH($B22,'Area safety'!$A$23:$A$41,0)),"n/a") -> 1
A23: Port Edward | B23: Banners Rest | C23: Available | D23: 570000 | E23: Apartment / Flat | F23: NOT STATED | G23: 2 | H23: 1 parking | I23: 84 | J23: 2295 | K23: 500 | L23: NOT STATED | M23: Yes | N23: Delightful two bedroom one bathroom apartment situated in a large well maintained security complex. | Pool, Garden | O23: Annette Mentz | P23: Chas Everitt KZN South Coast | Q23: NOT CAPTURED (reCAPTCHA) | R23: NOT AVAILABLE (needs phone) | S23: Agent profile | T23: Open listing | U23: 15 September 2023 | V23: 2026-10-08 | W23: =IFERROR(INDEX('Area safety'!$C$23:$C$41,MATCH($B23,'Area safety'!$A$23:$A$41,0)),"n/a") -> Port Edward | X23: =IFERROR(INDEX('Area safety'!$D$23:$D$41,MATCH($B23,'Area safety'!$A$23:$A$41,0)),"n/a") -> UNCONFIRMED - provisional (assumed Port Edward precinct) | Y23: =IFERROR(INDEX('Area safety'!$F$23:$F$41,MATCH($B23,'Area safety'!$A$23:$A$41,0)),"n/a") -> 571.8582 | Z23: =IFERROR(INDEX('Area safety'!$G$23:$G$41,MATCH($B23,'Area safety'!$A$23:$A$41,0)),"n/a") -> 596.91971 | AA23: =IFERROR(INDEX('Area safety'!$H$23:$H$41,MATCH($B23,'Area safety'!$A$23:$A$41,0)),"n/a") -> 27.339834 | AB23: =IFERROR(INDEX('Area safety'!$I$23:$I$41,MATCH($B23,'Area safety'!$A$23:$A$41,0)),"n/a") -> 2039.096 | AC23: =IFERROR(INDEX('Area safety'!$F$5:$F$18,MATCH($W23,'Area safety'!$A$5:$A$18,0)),"n/a") -> 895 | AD23: =IFERROR(INDEX('Area safety'!$G$5:$G$18,MATCH($W23,'Area safety'!$A$5:$A$18,0)),"n/a") -> 12 | AE23: =IFERROR(INDEX('Area safety'!$H$5:$H$18,MATCH($W23,'Area safety'!$A$5:$A$18,0)),"n/a") -> 251 | AF23: =IFERROR(INDEX('Area safety'!$I$5:$I$18,MATCH($W23,'Area safety'!$A$5:$A$18,0)),"n/a") -> 262 | AG23: =IFERROR(INDEX('Area safety'!$K$23:$K$41,MATCH($B23,'Area safety'!$A$23:$A$41,0)),"n/a") -> 0.083535109 | AH23: =IFERROR(INDEX('Area safety'!$J$23:$J$41,MATCH($B23,'Area safety'!$A$23:$A$41,0)),"n/a") -> 1
A24: Port Edward | B24: Banners Rest | C24: Available | D24: 580000 | E24: Apartment / Flat | F24: NOT STATED | G24: 2 | H24: 1 parking | I24: 91 | J24: 2900 | K24: 722 | L24: NOT STATED | M24: Yes | N24: If you've been dreaming of a secure, lock-up-and-go lifestyle surrounded by nature and exceptional recreational amenities, this could be the perfect p | Pool | O24: Tertia Sterley | P24: Property Port | Q24: NOT CAPTURED (reCAPTCHA) | R24: NOT AVAILABLE (needs phone) | S24: Agent profile | T24: Open listing | U24: 29 July 2026 | V24: 2026-10-08 | W24: =IFERROR(INDEX('Area safety'!$C$23:$C$41,MATCH($B24,'Area safety'!$A$23:$A$41,0)),"n/a") -> Port Edward | X24: =IFERROR(INDEX('Area safety'!$D$23:$D$41,MATCH($B24,'Area safety'!$A$23:$A$41,0)),"n/a") -> UNCONFIRMED - provisional (assumed Port Edward precinct) | Y24: =IFERROR(INDEX('Area safety'!$F$23:$F$41,MATCH($B24,'Area safety'!$A$23:$A$41,0)),"n/a") -> 571.8582 | Z24: =IFERROR(INDEX('Area safety'!$G$23:$G$41,MATCH($B24,'Area safety'!$A$23:$A$41,0)),"n/a") -> 596.91971 | AA24: =IFERROR(INDEX('Area safety'!$H$23:$H$41,MATCH($B24,'Area safety'!$A$23:$A$41,0)),"n/a") -> 27.339834 | AB24: =IFERROR(INDEX('Area safety'!$I$23:$I$41,MATCH($B24,'Area safety'!$A$23:$A$41,0)),"n/a") -> 2039.096 | AC24: =IFERROR(INDEX('Area safety'!$F$5:$F$18,MATCH($W24,'Area safety'!$A$5:$A$18,0)),"n/a") -> 895 | AD24: =IFERROR(INDEX('Area safety'!$G$5:$G$18,MATCH($W24,'Area safety'!$A$5:$A$18,0)),"n/a") -> 12 | AE24: =IFERROR(INDEX('Area safety'!$H$5:$H$18,MATCH($W24,'Area safety'!$A$5:$A$18,0)),"n/a") -> 251 | AF24: =IFERROR(INDEX('Area safety'!$I$5:$I$18,MATCH($W24,'Area safety'!$A$5:$A$18,0)),"n/a") -> 262 | AG24: =IFERROR(INDEX('Area safety'!$K$23:$K$41,MATCH($B24,'Area safety'!$A$23:$A$41,0)),"n/a") -> 0.083535109 | AH24: =IFERROR(INDEX('Area safety'!$J$23:$J$41,MATCH($B24,'Area safety'!$A$23:$A$41,0)),"n/a") -> 1
A25: Port Edward | B25: Banners Rest | C25: Available | D25: 580000 | E25: Apartment / Flat | F25: NOT STATED | G25: 2 | H25: NOT STATED | I25: 84 | J25: 3200 | K25: 644 | L25: NOT STATED | M25: NOT STATED | N25: Nestled in the tranquil Banners Rest area along the banks of the magnificent Umtamvuna River, this delightful unit at Eden Wilds offers the perfect op | Pool, Garden | O25: Brenda McNeil | P25: PdH Properties | Q25: NOT CAPTURED (reCAPTCHA) | R25: NOT AVAILABLE (needs phone) | S25: Agent profile | T25: Open listing | U25: 05 November 2025 | V25: 2026-10-08 | W25: =IFERROR(INDEX('Area safety'!$C$23:$C$41,MATCH($B25,'Area safety'!$A$23:$A$41,0)),"n/a") -> Port Edward | X25: =IFERROR(INDEX('Area safety'!$D$23:$D$41,MATCH($B25,'Area safety'!$A$23:$A$41,0)),"n/a") -> UNCONFIRMED - provisional (assumed Port Edward precinct) | Y25: =IFERROR(INDEX('Area safety'!$F$23:$F$41,MATCH($B25,'Area safety'!$A$23:$A$41,0)),"n/a") -> 571.8582 | Z25: =IFERROR(INDEX('Area safety'!$G$23:$G$41,MATCH($B25,'Area safety'!$A$23:$A$41,0)),"n/a") -> 596.91971 | AA25: =IFERROR(INDEX('Area safety'!$H$23:$H$41,MATCH($B25,'Area safety'!$A$23:$A$41,0)),"n/a") -> 27.339834 | AB25: =IFERROR(INDEX('Area safety'!$I$23:$I$41,MATCH($B25,'Area safety'!$A$23:$A$41,0)),"n/a") -> 2039.096 | AC25: =IFERROR(INDEX('Area safety'!$F$5:$F$18,MATCH($W25,'Area safety'!$A$5:$A$18,0)),"n/a") -> 895 | AD25: =IFERROR(INDEX('Area safety'!$G$5:$G$18,MATCH($W25,'Area safety'!$A$5:$A$18,0)),"n/a") -> 12 | AE25: =IFERROR(INDEX('Area safety'!$H$5:$H$18,MATCH($W25,'Area safety'!$A$5:$A$18,0)),"n/a") -> 251 | AF25: =IFERROR(INDEX('Area safety'!$I$5:$I$18,MATCH($W25,'Area safety'!$A$5:$A$18,0)),"n/a") -> 262 | AG25: =IFERROR(INDEX('Area safety'!$K$23:$K$41,MATCH($B25,'Area safety'!$A$23:$A$41,0)),"n/a") -> 0.083535109 | AH25: =IFERROR(INDEX('Area safety'!$J$23:$J$41,MATCH($B25,'Area safety'!$A$23:$A$41,0)),"n/a") -> 1
A26: Port Edward | B26: Banners Rest | C26: Available | D26: 595000 | E26: Apartment / Flat | F26: NOT STATED | G26: 2 | H26: 1 garage | I26: 91 | J26: NOT STATED | K26: NOT STATED | L26: No | M26: NOT STATED | N26: SOLE MANDATE This lovely remarkable unit is situated in an immaculate well maintained block just minutes away from the beach close to schools, shoppin | No Pets Allowed, Pool | O26: Rene Houghton | P26: Property.CoZa - Communities | Q26: NOT CAPTURED (reCAPTCHA) | R26: NOT AVAILABLE (needs phone) | S26: Agent profile | T26: Open listing | U26: 13 July 2025 | V26: 2026-10-08 | W26: =IFERROR(INDEX('Area safety'!$C$23:$C$41,MATCH($B26,'Area safety'!$A$23:$A$41,0)),"n/a") -> Port Edward | X26: =IFERROR(INDEX('Area safety'!$D$23:$D$41,MATCH($B26,'Area safety'!$A$23:$A$41,0)),"n/a") -> UNCONFIRMED - provisional (assumed Port Edward precinct) | Y26: =IFERROR(INDEX('Area safety'!$F$23:$F$41,MATCH($B26,'Area safety'!$A$23:$A$41,0)),"n/a") -> 571.8582 | Z26: =IFERROR(INDEX('Area safety'!$G$23:$G$41,MATCH($B26,'Area safety'!$A$23:$A$41,0)),"n/a") -> 596.91971 | AA26: =IFERROR(INDEX('Area safety'!$H$23:$H$41,MATCH($B26,'Area safety'!$A$23:$A$41,0)),"n/a") -> 27.339834 | AB26: =IFERROR(INDEX('Area safety'!$I$23:$I$41,MATCH($B26,'Area safety'!$A$23:$A$41,0)),"n/a") -> 2039.096 | AC26: =IFERROR(INDEX('Area safety'!$F$5:$F$18,MATCH($W26,'Area safety'!$A$5:$A$18,0)),"n/a") -> 895 | AD26: =IFERROR(INDEX('Area safety'!$G$5:$G$18,MATCH($W26,'Area safety'!$A$5:$A$18,0)),"n/a") -> 12 | AE26: =IFERROR(INDEX('Area safety'!$H$5:$H$18,MATCH($W26,'Area safety'!$A$5:$A$18,0)),"n/a") -> 251 | AF26: =IFERROR(INDEX('Area safety'!$I$5:$I$18,MATCH($W26,'Area safety'!$A$5:$A$18,0)),"n/a") -> 262 | AG26: =IFERROR(INDEX('Area safety'!$K$23:$K$41,MATCH($B26,'Area safety'!$A$23:$A$41,0)),"n/a") -> 0.083535109 | AH26: =IFERROR(INDEX('Area safety'!$J$23:$J$41,MATCH($B26,'Area safety'!$A$23:$A$41,0)),"n/a") -> 1
A27: Port Edward | B27: Banners Rest | C27: Available | D27: 599000 | E27: Apartment / Flat | F27: NOT STATED | G27: 2 | H27: NOT STATED | I27: 84 | J27: 1977 | K27: 580 | L27: No | M27: Yes | N27: This Complex is an inviting Lush Tropical PARADISE, surrounded by picturesque mountain views and the Umthumvuna river. | No Pets Allowed, Pool | O27: Stephanie Harries | P27: Wakefields Estate Agents Shelly Beach | Q27: NOT CAPTURED (reCAPTCHA) | R27: NOT AVAILABLE (needs phone) | S27: Agent profile | T27: Open listing | U27: 13 January 2020 | V27: 2026-10-08 | W27: =IFERROR(INDEX('Area safety'!$C$23:$C$41,MATCH($B27,'Area safety'!$A$23:$A$41,0)),"n/a") -> Port Edward | X27: =IFERROR(INDEX('Area safety'!$D$23:$D$41,MATCH($B27,'Area safety'!$A$23:$A$41,0)),"n/a") -> UNCONFIRMED - provisional (assumed Port Edward precinct) | Y27: =IFERROR(INDEX('Area safety'!$F$23:$F$41,MATCH($B27,'Area safety'!$A$23:$A$41,0)),"n/a") -> 571.8582 | Z27: =IFERROR(INDEX('Area safety'!$G$23:$G$41,MATCH($B27,'Area safety'!$A$23:$A$41,0)),"n/a") -> 596.91971 | AA27: =IFERROR(INDEX('Area safety'!$H$23:$H$41,MATCH($B27,'Area safety'!$A$23:$A$41,0)),"n/a") -> 27.339834 | AB27: =IFERROR(INDEX('Area safety'!$I$23:$I$41,MATCH($B27,'Area safety'!$A$23:$A$41,0)),"n/a") -> 2039.096 | AC27: =IFERROR(INDEX('Area safety'!$F$5:$F$18,MATCH($W27,'Area safety'!$A$5:$A$18,0)),"n/a") -> 895 | AD27: =IFERROR(INDEX('Area safety'!$G$5:$G$18,MATCH($W27,'Area safety'!$A$5:$A$18,0)),"n/a") -> 12 | AE27: =IFERROR(INDEX('Area safety'!$H$5:$H$18,MATCH($W27,'Area safety'!$A$5:$A$18,0)),"n/a") -> 251 | AF27: =IFERROR(INDEX('Area safety'!$I$5:$I$18,MATCH($W27,'Area safety'!$A$5:$A$18,0)),"n/a") -> 262 | AG27: =IFERROR(INDEX('Area safety'!$K$23:$K$41,MATCH($B27,'Area safety'!$A$23:$A$41,0)),"n/a") -> 0.083535109 | AH27: =IFERROR(INDEX('Area safety'!$J$23:$J$41,MATCH($B27,'Area safety'!$A$23:$A$41,0)),"n/a") -> 1
A28: Port Edward | B28: Banners Rest | C28: Available | D28: 600000 | E28: Apartment / Flat | F28: NOT STATED | G28: 2 | H28: 1 garage | I28: 86 | J28: 1650 | K28: 629 | L28: Yes | M28: Optional | N28: Words and photos cannot fully capture the breathtaking views from this stunning upstairs 2-bedroom, 2-bathroom unit at Eden Crest – 24 Maurice Road, B | Pet Friendly, Pool, Garden | O28: Brenda McNeil | P28: PdH Properties | Q28: NOT CAPTURED (reCAPTCHA) | R28: NOT AVAILABLE (needs phone) | S28: Agent profile | T28: Open listing | U28: 22 February 2025 | V28: 2026-10-08 | W28: =IFERROR(INDEX('Area safety'!$C$23:$C$41,MATCH($B28,'Area safety'!$A$23:$A$41,0)),"n/a") -> Port Edward | X28: =IFERROR(INDEX('Area safety'!$D$23:$D$41,MATCH($B28,'Area safety'!$A$23:$A$41,0)),"n/a") -> UNCONFIRMED - provisional (assumed Port Edward precinct) | Y28: =IFERROR(INDEX('Area safety'!$F$23:$F$41,MATCH($B28,'Area safety'!$A$23:$A$41,0)),"n/a") -> 571.8582 | Z28: =IFERROR(INDEX('Area safety'!$G$23:$G$41,MATCH($B28,'Area safety'!$A$23:$A$41,0)),"n/a") -> 596.91971 | AA28: =IFERROR(INDEX('Area safety'!$H$23:$H$41,MATCH($B28,'Area safety'!$A$23:$A$41,0)),"n/a") -> 27.339834 | AB28: =IFERROR(INDEX('Area safety'!$I$23:$I$41,MATCH($B28,'Area safety'!$A$23:$A$41,0)),"n/a") -> 2039.096 | AC28: =IFERROR(INDEX('Area safety'!$F$5:$F$18,MATCH($W28,'Area safety'!$A$5:$A$18,0)),"n/a") -> 895 | AD28: =IFERROR(INDEX('Area safety'!$G$5:$G$18,MATCH($W28,'Area safety'!$A$5:$A$18,0)),"n/a") -> 12 | AE28: =IFERROR(INDEX('Area safety'!$H$5:$H$18,MATCH($W28,'Area safety'!$A$5:$A$18,0)),"n/a") -> 251 | AF28: =IFERROR(INDEX('Area safety'!$I$5:$I$18,MATCH($W28,'Area safety'!$A$5:$A$18,0)),"n/a") -> 262 | AG28: =IFERROR(INDEX('Area safety'!$K$23:$K$41,MATCH($B28,'Area safety'!$A$23:$A$41,0)),"n/a") -> 0.083535109 | AH28: =IFERROR(INDEX('Area safety'!$J$23:$J$41,MATCH($B28,'Area safety'!$A$23:$A$41,0)),"n/a") -> 1
A29: Port Edward | B29: Banners Rest | C29: Available | D29: 600000 | E29: Apartment / Flat | F29: NOT STATED | G29: 2 | H29: 1 garage | I29: 97 | J29: 680 | K29: 1600 | L29: Yes | M29: NOT STATED | N29: Nestled in the heart of Banners Rest, this charming 2-bedroom, 2-bathroom apartment offers the perfect blend of comfort, convenience, and natural beauty. | Pet Friendly, Pool | O29: Stephanie Harries | P29: Wakefields Estate Agents Shelly Beach | Q29: NOT CAPTURED (reCAPTCHA) | R29: NOT AVAILABLE (needs phone) | S29: Agent profile | T29: Open listing | U29: 02 April 2025 | V29: 2026-10-08 | W29: =IFERROR(INDEX('Area safety'!$C$23:$C$41,MATCH($B29,'Area safety'!$A$23:$A$41,0)),"n/a") -> Port Edward | X29: =IFERROR(INDEX('Area safety'!$D$23:$D$41,MATCH($B29,'Area safety'!$A$23:$A$41,0)),"n/a") -> UNCONFIRMED - provisional (assumed Port Edward precinct) | Y29: =IFERROR(INDEX('Area safety'!$F$23:$F$41,MATCH($B29,'Area safety'!$A$23:$A$41,0)),"n/a") -> 571.8582 | Z29: =IFERROR(INDEX('Area safety'!$G$23:$G$41,MATCH($B29,'Area safety'!$A$23:$A$41,0)),"n/a") -> 596.91971 | AA29: =IFERROR(INDEX('Area safety'!$H$23:$H$41,MATCH($B29,'Area safety'!$A$23:$A$41,0)),"n/a") -> 27.339834 | AB29: =IFERROR(INDEX('Area safety'!$I$23:$I$41,MATCH($B29,'Area safety'!$A$23:$A$41,0)),"n/a") -> 2039.096 | AC29: =IFERROR(INDEX('Area safety'!$F$5:$F$18,MATCH($W29,'Area safety'!$A$5:$A$18,0)),"n/a") -> 895 | AD29: =IFERROR(INDEX('Area safety'!$G$5:$G$18,MATCH($W29,'Area safety'!$A$5:$A$18,0)),"n/a") -> 12 | AE29: =IFERROR(INDEX('Area safety'!$H$5:$H$18,MATCH($W29,'Area safety'!$A$5:$A$18,0)),"n/a") -> 251 | AF29: =IFERROR(INDEX('Area safety'!$I$5:$I$18,MATCH($W29,'Area safety'!$A$5:$A$18,0)),"n/a") -> 262 | AG29: =IFERROR(INDEX('Area safety'!$K$23:$K$41,MATCH($B29,'Area safety'!$A$23:$A$41,0)),"n/a") -> 0.083535109 | AH29: =IFERROR(INDEX('Area safety'!$J$23:$J$41,MATCH($B29,'Area safety'!$A$23:$A$41,0)),"n/a") -> 1
A30: Port Edward | B30: Banners Rest | C30: Available | D30: 620000 | E30: Apartment / Flat | F30: NOT STATED | G30: 2 | H30: NOT STATED | I30: 84 | J30: 2200 | K30: 630 | L30: No | M30: Yes | N30: This is a beautiful well maintained 2-bedroom unit on the Umtumvuna River. | No Pets Allowed, Pool, Garden | O30: Belinda Jamieson | P30: Seeff Hibiscus Coast | Q30: NOT CAPTURED (reCAPTCHA) | R30: NOT AVAILABLE (needs phone) | S30: Agent profile | T30: Open listing | U30: 11 May 2022 | V30: 2026-10-08 | W30: =IFERROR(INDEX('Area safety'!$C$23:$C$41,MATCH($B30,'Area safety'!$A$23:$A$41,0)),"n/a") -> Port Edward | X30: =IFERROR(INDEX('Area safety'!$D$23:$D$41,MATCH($B30,'Area safety'!$A$23:$A$41,0)),"n/a") -> UNCONFIRMED - provisional (assumed Port Edward precinct) | Y30: =IFERROR(INDEX('Area safety'!$F$23:$F$41,MATCH($B30,'Area safety'!$A$23:$A$41,0)),"n/a") -> 571.8582 | Z30: =IFERROR(INDEX('Area safety'!$G$23:$G$41,MATCH($B30,'Area safety'!$A$23:$A$41,0)),"n/a") -> 596.91971 | AA30: =IFERROR(INDEX('Area safety'!$H$23:$H$41,MATCH($B30,'Area safety'!$A$23:$A$41,0)),"n/a") -> 27.339834 | AB30: =IFERROR(INDEX('Area safety'!$I$23:$I$41,MATCH($B30,'Area safety'!$A$23:$A$41,0)),"n/a") -> 2039.096 | AC30: =IFERROR(INDEX('Area safety'!$F$5:$F$18,MATCH($W30,'Area safety'!$A$5:$A$18,0)),"n/a") -> 895 | AD30: =IFERROR(INDEX('Area safety'!$G$5:$G$18,MATCH($W30,'Area safety'!$A$5:$A$18,0)),"n/a") -> 12 | AE30: =IFERROR(INDEX('Area safety'!$H$5:$H$18,MATCH($W30,'Area safety'!$A$5:$A$18,0)),"n/a") -> 251 | AF30: =IFERROR(INDEX('Area safety'!$I$5:$I$18,MATCH($W30,'Area safety'!$A$5:$A$18,0)),"n/a") -> 262 | AG30: =IFERROR(INDEX('Area safety'!$K$23:$K$41,MATCH($B30,'Area safety'!$A$23:$A$41,0)),"n/a") -> 0.083535109 | AH30: =IFERROR(INDEX('Area safety'!$J$23:$J$41,MATCH($B30,'Area safety'!$A$23:$A$41,0)),"n/a") -> 1
A31: Port Edward | B31: Banners Rest | C31: Available | D31: 630000 | E31: Apartment / Flat | F31: NOT STATED | G31: 2 | H31: 1 parking | I31: 84 | J31: 2197 | K31: 634 | L31: No | M31: Yes | N31: This Complex is idyllic setting. | No Pets Allowed, Pool | O31: Stephanie Harries | P31: Wakefields Estate Agents Shelly Beach | Q31: NOT CAPTURED (reCAPTCHA) | R31: NOT AVAILABLE (needs phone) | S31: Agent profile | T31: Open listing | U31: 20 September 2019 | V31: 2026-10-08 | W31: =IFERROR(INDEX('Area safety'!$C$23:$C$41,MATCH($B31,'Area safety'!$A$23:$A$41,0)),"n/a") -> Port Edward | X31: =IFERROR(INDEX('Area safety'!$D$23:$D$41,MATCH($B31,'Area safety'!$A$23:$A$41,0)),"n/a") -> UNCONFIRMED - provisional (assumed Port Edward precinct) | Y31: =IFERROR(INDEX('Area safety'!$F$23:$F$41,MATCH($B31,'Area safety'!$A$23:$A$41,0)),"n/a") -> 571.8582 | Z31: =IFERROR(INDEX('Area safety'!$G$23:$G$41,MATCH($B31,'Area safety'!$A$23:$A$41,0)),"n/a") -> 596.91971 | AA31: =IFERROR(INDEX('Area safety'!$H$23:$H$41,MATCH($B31,'Area safety'!$A$23:$A$41,0)),"n/a") -> 27.339834 | AB31: =IFERROR(INDEX('Area safety'!$I$23:$I$41,MATCH($B31,'Area safety'!$A$23:$A$41,0)),"n/a") -> 2039.096 | AC31: =IFERROR(INDEX('Area safety'!$F$5:$F$18,MATCH($W31,'Area safety'!$A$5:$A$18,0)),"n/a") -> 895 | AD31: =IFERROR(INDEX('Area safety'!$G$5:$G$18,MATCH($W31,'Area safety'!$A$5:$A$18,0)),"n/a") -> 12 | AE31: =IFERROR(INDEX('Area safety'!$H$5:$H$18,MATCH($W31,'Area safety'!$A$5:$A$18,0)),"n/a") -> 251 | AF31: =IFERROR(INDEX('Area safety'!$I$5:$I$18,MATCH($W31,'Area safety'!$A$5:$A$18,0)),"n/a") -> 262 | AG31: =IFERROR(INDEX('Area safety'!$K$23:$K$41,MATCH($B31,'Area safety'!$A$23:$A$41,0)),"n/a") -> 0.083535109 | AH31: =IFERROR(INDEX('Area safety'!$J$23:$J$41,MATCH($B31,'Area safety'!$A$23:$A$41,0)),"n/a") -> 1
A32: Port Edward | B32: Banners Rest | C32: Available | D32: 650000 | E32: Apartment / Flat | F32: NOT STATED | G32: 2 | H32: 1 parking | I32: 84 | J32: 2500 | K32: 650 | L32: No | M32: NOT STATED | N32: Discover the perfect blend of comfort, nature and secure estate living in this beautiful two-bedroom apartment in the sought-after Eden Wilds The spac | No Pets Allowed, Pool, Garden | O32: Judy Rademeyer | P32: Real Estate Services | Q32: NOT CAPTURED (reCAPTCHA) | R32: NOT AVAILABLE (needs phone) | S32: Agent profile | T32: Open listing | U32: 16 August 2026 | V32: 2026-10-08 | W32: =IFERROR(INDEX('Area safety'!$C$23:$C$41,MATCH($B32,'Area safety'!$A$23:$A$41,0)),"n/a") -> Port Edward | X32: =IFERROR(INDEX('Area safety'!$D$23:$D$41,MATCH($B32,'Area safety'!$A$23:$A$41,0)),"n/a") -> UNCONFIRMED - provisional (assumed Port Edward precinct) | Y32: =IFERROR(INDEX('Area safety'!$F$23:$F$41,MATCH($B32,'Area safety'!$A$23:$A$41,0)),"n/a") -> 571.8582 | Z32: =IFERROR(INDEX('Area safety'!$G$23:$G$41,MATCH($B32,'Area safety'!$A$23:$A$41,0)),"n/a") -> 596.91971 | AA32: =IFERROR(INDEX('Area safety'!$H$23:$H$41,MATCH($B32,'Area safety'!$A$23:$A$41,0)),"n/a") -> 27.339834 | AB32: =IFERROR(INDEX('Area safety'!$I$23:$I$41,MATCH($B32,'Area safety'!$A$23:$A$41,0)),"n/a") -> 2039.096 | AC32: =IFERROR(INDEX('Area safety'!$F$5:$F$18,MATCH($W32,'Area safety'!$A$5:$A$18,0)),"n/a") -> 895 | AD32: =IFERROR(INDEX('Area safety'!$G$5:$G$18,MATCH($W32,'Area safety'!$A$5:$A$18,0)),"n/a") -> 12 | AE32: =IFERROR(INDEX('Area safety'!$H$5:$H$18,MATCH($W32,'Area safety'!$A$5:$A$18,0)),"n/a") -> 251 | AF32: =IFERROR(INDEX('Area safety'!$I$5:$I$18,MATCH($W32,'Area safety'!$A$5:$A$18,0)),"n/a") -> 262 | AG32: =IFERROR(INDEX('Area safety'!$K$23:$K$41,MATCH($B32,'Area safety'!$A$23:$A$41,0)),"n/a") -> 0.083535109 | AH32: =IFERROR(INDEX('Area safety'!$J$23:$J$41,MATCH($B32,'Area safety'!$A$23:$A$41,0)),"n/a") -> 1
A33: Port Edward | B33: Banners Rest | C33: Available | D33: 650000 | E33: Apartment / Flat | F33: NOT STATED | G33: 2 | H33: 1 parking | I33: 84 | J33: 3500 | K33: 678 | L33: No | M33: NOT STATED | N33: Imagine stepping out of your open-plan lounge onto a verandah that looks out onto lush greenery, where the only sounds you hear are the gentle rustle | No Pets Allowed, Pool | O33: Tina Sykes | P33: Real Estate Services | Q33: NOT CAPTURED (reCAPTCHA) | R33: NOT AVAILABLE (needs phone) | S33: Agent profile | T33: Open listing | U33: 19 June 2026 | V33: 2026-10-08 | W33: =IFERROR(INDEX('Area safety'!$C$23:$C$41,MATCH($B33,'Area safety'!$A$23:$A$41,0)),"n/a") -> Port Edward | X33: =IFERROR(INDEX('Area safety'!$D$23:$D$41,MATCH($B33,'Area safety'!$A$23:$A$41,0)),"n/a") -> UNCONFIRMED - provisional (assumed Port Edward precinct) | Y33: =IFERROR(INDEX('Area safety'!$F$23:$F$41,MATCH($B33,'Area safety'!$A$23:$A$41,0)),"n/a") -> 571.8582 | Z33: =IFERROR(INDEX('Area safety'!$G$23:$G$41,MATCH($B33,'Area safety'!$A$23:$A$41,0)),"n/a") -> 596.91971 | AA33: =IFERROR(INDEX('Area safety'!$H$23:$H$41,MATCH($B33,'Area safety'!$A$23:$A$41,0)),"n/a") -> 27.339834 | AB33: =IFERROR(INDEX('Area safety'!$I$23:$I$41,MATCH($B33,'Area safety'!$A$23:$A$41,0)),"n/a") -> 2039.096 | AC33: =IFERROR(INDEX('Area safety'!$F$5:$F$18,MATCH($W33,'Area safety'!$A$5:$A$18,0)),"n/a") -> 895 | AD33: =IFERROR(INDEX('Area safety'!$G$5:$G$18,MATCH($W33,'Area safety'!$A$5:$A$18,0)),"n/a") -> 12 | AE33: =IFERROR(INDEX('Area safety'!$H$5:$H$18,MATCH($W33,'Area safety'!$A$5:$A$18,0)),"n/a") -> 251 | AF33: =IFERROR(INDEX('Area safety'!$I$5:$I$18,MATCH($W33,'Area safety'!$A$5:$A$18,0)),"n/a") -> 262 | AG33: =IFERROR(INDEX('Area safety'!$K$23:$K$41,MATCH($B33,'Area safety'!$A$23:$A$41,0)),"n/a") -> 0.083535109 | AH33: =IFERROR(INDEX('Area safety'!$J$23:$J$41,MATCH($B33,'Area safety'!$A$23:$A$41,0)),"n/a") -> 1
